Workbook
Name CSV_file: 'Full 1801-31 data set'!#REF!
Name CSV_file_1: 'Full 1801-31 data set'!#REF!

Sheet Full 1801-31 data set
A1: Parishes - the most local level at which data were collected | B1: Categories / Groups - for use when sorting, filtering and/or summarising data | M1: Raw data from the 1801 census | S1: 'Indicators' calculated from the 1801 census raw data | Z1: Later censuses | AC1: Population growth rates (calculated) | AG1: 1815 annual property values, and calculated indicators
A3: Parish | B3: User-selected | C3: Hundred | D3: Hundred code | E3: Market Town? | F3: Other Towns | G3: Deanery (old) | H3: Deanery code | I3: Modern District | J3: Modern District code | K3: Vancouver District | L3: Vancouver Order | M3: Houses occupied 1801 | N3: Families 1801 | O3: Agric empl 1801 | P3: Mftg (etc) empl 1801 | Q3: Other occ 1801 | R3: Popn 1801 | S3: Family size | T3: Ag/Popn | U3: Ind (etc)/ Popn | V3: Other/Popn | W3: Ind (etc)/ Ag | X3: Other/Ag + Ind (etc) | Y3: Parish as % of Devon | Z3: Popn 1811 | AA3: Popn 1821 | AB3: Popn 1831 | AC3: Popn11/ Popn01 | AD3: Popn21/ Popn11 | AE3: Popn31/ Popn21 | AF3: Popn31/ Popn01 | AG3: Popn 1815 (est) | AH3: Property value 1815 | AI3: Value (£ per capita) | AJ3: Val/cap as % of Devon av
A4: Abbots Bickington | C4: Black Torrington | D4: 3 | G4: Holsworthy | H4: 9 | I4: Torridge | J4: 9 | K4: 3 | L4: 1 | M4: 10 | N4: 12 | O4: 30 | P4: 0 | Q4: 38 | R4: 68 | S4: =R4/N4 -> 5.6666667 | T4: =O4/R4 -> 0.44117647 | U4: =P4/R4 -> 0 | V4: =Q4/R4 -> 0.55882353 | W4: =P4/O4 -> 0 | X4: =Q4/(O4+P4) -> 1.2666667 | Y4: =R4/R$488 -> 0.00019753718 | Z4: 72 | AA4: 75 | AB4: 77 | AC4: =Z4/R4 -> 1.0588235 | AD4: =AA4/Z4 -> 1.0416667 | AE4: =AB4/AA4 -> 1.0266667 | AF4: =AB4/R4 -> 1.1323529 | AG4: =0.6*Z4+0.4*AA4 -> 73.2 | AH4: 424 | AI4: =AH4/AG4 -> 5.7923497 | AJ4: =AI4/AI$488 -> 1.2308994
A5: Abbotsham | C5: Shebbear | D5: 23 | G5: Hartland | H5: 8 | I5: Torridge | J5: 9 | K5: 1 | L5: 2 | M5: 59 | N5: 59 | O5: 305 | P5: 8 | Q5: 0 | R5: 313 | S5: =R5/N5 -> 5.3050847 | T5: =O5/R5 -> 0.97444089 | U5: =P5/R5 -> 0.025559105 | V5: =Q5/R5 -> 0 | W5: =P5/O5 -> 0.026229508 | X5: =Q5/(O5+P5) -> 0 | Y5: =R5/R$488 -> 0.000909252 | Z5: 321 | AA5: 386 | AB5: 387 | AC5: =Z5/R5 -> 1.0255591 | AD5: =AA5/Z5 -> 1.2024922 | AE5: =AB5/AA5 -> 1.0025907 | AF5: =AB5/R5 -> 1.2364217 | AG5: =0.6*Z5+0.4*AA5 -> 347 | AH5: 2481 | AI5: =AH5/AG5 -> 7.1498559 | AJ5: =AI5/AI$488 -> 1.5193753
A6: Abbotskerswell | C6: Haytor | D6: 16 | G6: Ipplepen | H6: 11 | I6: Teignbridge | J6: 5 | K6: 4 | L6: 4 | M6: 95 | N6: 95 | O6: 101 | P6: 122 | Q6: 166 | R6: 389 | S6: =R6/N6 -> 4.0947368 | T6: =O6/R6 -> 0.2596401 | U6: =P6/R6 -> 0.31362468 | V6: =Q6/R6 -> 0.42673522 | W6: =P6/O6 -> 1.2079208 | X6: =Q6/(O6+P6) -> 0.74439462 | Y6: =R6/R$488 -> 0.0011300288 | Z6: 379 | AA6: 437 | AB6: 442 | AC6: =Z6/R6 -> 0.97429306 | AD6: =AA6/Z6 -> 1.1530343 | AE6: =AB6/AA6 -> 1.0114416 | AF6: =AB6/R6 -> 1.1362468 | AG6: =0.6*Z6+0.4*AA6 -> 402.2 | AH6: 2902 | AI6: =AH6/AG6 -> 7.2153158 | AJ6: =AI6/AI$488 -> 1.5332858
A7: Alphington | C7: Wonford | D7: 32 | G7: Kenn | H7: 12 | I7: Exeter | J7: 1 | K7: 6 | L7: 2 | M7: 98 | N7: 184 | O7: 114 | P7: 42 | Q7: 689 | R7: 845 | S7: =R7/N7 -> 4.5923913 | T7: =O7/R7 -> 0.13491124 | U7: =P7/R7 -> 0.049704142 | V7: =Q7/R7 -> 0.81538462 | W7: =P7/O7 -> 0.36842105 | X7: =Q7/(O7+P7) -> 4.4166667 | Y7: =R7/R$488 -> 0.0024546899 | Z7: 911 | AA7: 1070 | AB7: 1236 | AC7: =Z7/R7 -> 1.0781065 | AD7: =AA7/Z7 -> 1.1745335 | AE7: =AB7/AA7 -> 1.1551402 | AF7: =AB7/R7 -> 1.4627219 | AG7: =0.6*Z7+0.4*AA7 -> 974.6 | AH7: 6999 | AI7: =AH7/AG7 -> 7.1814078 | AJ7: =AI7/AI$488 -> 1.5260802
A8: Alverdiscott | C8: Fremington | D8: 12 | G8: Hartland | H8: 8 | I8: Torridge | J8: 9 | K8: 1 | L8: 3 | M8: 52 | N8: 52 | O8: 161 | P8: 7 | Q8: 110 | R8: 278 | S8: =R8/N8 -> 5.3461538 | T8: =O8/R8 -> 0.57913669 | U8: =P8/R8 -> 0.025179856 | V8: =Q8/R8 -> 0.39568345 | W8: =P8/O8 -> 0.043478261 | X8: =Q8/(O8+P8) -> 0.6547619 | Y8: =R8/R$488 -> 0.00080757846 | Z8: 257 | AA8: 334 | AB8: 339 | AC8: =Z8/R8 -> 0.92446043 | AD8: =AA8/Z8 -> 1.2996109 | AE8: =AB8/AA8 -> 1.0149701 | AF8: =AB8/R8 -> 1.2194245 | AG8: =0.6*Z8+0.4*AA8 -> 287.8 | AH8: 1431 | AI8: =AH8/AG8 -> 4.9722029 | AJ8: =AI8/AI$488 -> 1.0566146
A9: Alwington | C9: Shebbear | D9: 23 | G9: Hartland | H9: 8 | I9: Torridge | J9: 9 | K9: 1 | L9: 1 | M9: 56 | N9: 61 | O9: 83 | P9: 21 | Q9: 206 | R9: 310 | S9: =R9/N9 -> 5.0819672 | T9: =O9/R9 -> 0.26774194 | U9: =P9/R9 -> 0.067741935 | V9: =Q9/R9 -> 0.66451613 | W9: =P9/O9 -> 0.25301205 | X9: =Q9/(O9+P9) -> 1.9807692 | Y9: =R9/R$488 -> 0.00090053713 | Z9: 359 | AA9: 386 | AB9: 486 | AC9: =Z9/R9 -> 1.1580645 | AD9: =AA9/Z9 -> 1.0752089 | AE9: =AB9/AA9 -> 1.2590674 | AF9: =AB9/R9 -> 1.5677419 | AG9: =0.6*Z9+0.4*AA9 -> 369.8 | AH9: 2303 | AI9: =AH9/AG9 -> 6.2276906 | AJ9: =AI9/AI$488 -> 1.3234112
A10: Arlington | C10: Shirwell | D10: 24 | G10: Shirwell | H10: 17 | I10: North Devon | J10: 10 | K10: 1 | L10: 5 | M10: 37 | N10: 42 | O10: 87 | P10: 24 | Q10: 96 | R10: 207 | S10: =R10/N10 -> 4.9285714 | T10: =O10/R10 -> 0.42028986 | U10: =P10/R10 -> 0.11594203 | V10: =Q10/R10 -> 0.46376812 | W10: =P10/O10 -> 0.27586207 | X10: =Q10/(O10+P10) -> 0.86486486 | Y10: =R10/R$488 -> 0.0006013264 | Z10: 157 | AA10: 177 | AB10: 235 | AC10: =Z10/R10 -> 0.75845411 | AD10: =AA10/Z10 -> 1.1273885 | AE10: =AB10/AA10 -> 1.3276836 | AF10: =AB10/R10 -> 1.1352657 | AG10: =0.6*Z10+0.4*AA10 -> 165 | AH10: 1709 | AI10: =AH10/AG10 -> 10.357576 | AJ10: =AI10/AI$488 -> 2.2010297
A11: Ashburton | C11: Teignbridge | D11: 28 | E11: Yes | G11: Moreton | H11: 13 | I11: Teignbridge | J11: 5 | K11: 4 | L11: 3 | M11: 369 | N11: 664 | O11: 141 | P11: 267 | Q11: 2672 | R11: 3080 | S11: =R11/N11 -> 4.6385542 | T11: =O11/R11 -> 0.045779221 | U11: =P11/R11 -> 0.086688312 | V11: =Q11/R11 -> 0.86753247 | W11: =P11/O11 -> 1.893617 | X11: =Q11/(O11+P11) -> 6.5490196 | Y11: =R11/R$488 -> 0.0089472721 | Z11: 3053 | AA11: 3403 | AB11: 4165 | AC11: =Z11/R11 -> 0.99123377 | AD11: =AA11/Z11 -> 1.1146413 | AE11: =AB11/AA11 -> 1.2239201 | AF11: =AB11/R11 -> 1.3522727 | AG11: =0.6*Z11+0.4*AA11 -> 3193 | AH11: 7848 | AI11: =AH11/AG11 -> 2.4578766 | AJ11: =AI11/AI$488 -> 0.52230941
A12: Ashbury | C12: Black Torrington | D12: 3 | G12: Okehampton | H12: 14 | I12: West Devon | J12: 8 | K12: 3 | L12: 3 | M12: 4 | N12: 4 | O12: 20 | P12: 0 | Q12: 21 | R12: 41 | S12: =R12/N12 -> 10.25 | T12: =O12/R12 -> 0.48780488 | U12: =P12/R12 -> 0 | V12: =Q12/R12 -> 0.51219512 | W12: =P12/O12 -> 0 | X12: =Q12/(O12+P12) -> 1.05 | Y12: =R12/R$488 -> 0.0001191033 | Z12: 72 | AA12: 74 | AB12: 74 | AC12: =Z12/R12 -> 1.7560976 | AD12: =AA12/Z12 -> 1.0277778 | AE12: =AB12/AA12 -> 1 | AF12: =AB12/R12 -> 1.804878 | AG12: =0.6*Z12+0.4*AA12 -> 72.8 | AH12: 508 | AI12: =AH12/AG12 -> 6.978022 | AJ12: =AI12/AI$488 -> 1.4828599
A13: Ashcombe | C13: Exminster | D13: 11 | G13: Kenn | H13: 12 | I13: Teignbridge | J13: 5 | K13: 6 | L13: 1 | M13: 51 | N13: 57 | O13: 124 | P13: 8 | Q13: 148 | R13: 280 | S13: =R13/N13 -> 4.9122807 | T13: =O13/R13 -> 0.44285714 | U13: =P13/R13 -> 0.028571429 | V13: =Q13/R13 -> 0.52857143 | W13: =P13/O13 -> 0.064516129 | X13: =Q13/(O13+P13) -> 1.1212121 | Y13: =R13/R$488 -> 0.00081338837 | Z13: 272 | AA13: 283 | AB13: 320 | AC13: =Z13/R13 -> 0.97142857 | AD13: =AA13/Z13 -> 1.0404412 | AE13: =AB13/AA13 -> 1.130742 | AF13: =AB13/R13 -> 1.1428571 | AG13: =0.6*Z13+0.4*AA13 -> 276.4 | AH13: 1341 | AI13: =AH13/AG13 -> 4.8516643 | AJ13: =AI13/AI$488 -> 1.0309996
A14: Ashford | C14: Braunton | D14: 4 | G14: Shirwell | H14: 17 | I14: North Devon | J14: 10 | K14: 1 | L14: 6 | M14: 18 | N14: 21 | O14: 38 | P14: 10 | Q14: 25 | R14: 73 | S14: =R14/N14 -> 3.4761905 | T14: =O14/R14 -> 0.52054795 | U14: =P14/R14 -> 0.1369863 | V14: =Q14/R14 -> 0.34246575 | W14: =P14/O14 -> 0.26315789 | X14: =Q14/(O14+P14) -> 0.52083333 | Y14: =R14/R$488 -> 0.00021206197 | Z14: 101 | AA14: 98 | AB14: 99 | AC14: =Z14/R14 -> 1.3835616 | AD14: =AA14/Z14 -> 0.97029703 | AE14: =AB14/AA14 -> 1.0102041 | AF14: =AB14/R14 -> 1.3561644 | AG14: =0.6*Z14+0.4*AA14 -> 99.8 | AH14: 662 | AI14: =AH14/AG14 -> 6.6332665 | AJ14: =AI14/AI$488 -> 1.4095978
A15: Ashprington | C15: Coleridge | D15: 6 | G15: Totnes | H15: 24 | I15: South Hams | J15: 4 | K15: 4 | L15: 2 | M15: 96 | N15: 99 | O15: 215 | P15: 114 | Q15: 180 | R15: 509 | S15: =R15/N15 -> 5.1414141 | T15: =O15/R15 -> 0.42239686 | U15: =P15/R15 -> 0.22396857 | V15: =Q15/R15 -> 0.35363458 | W15: =P15/O15 -> 0.53023256 | X15: =Q15/(O15+P15) -> 0.54711246 | Y15: =R15/R$488 -> 0.0014786239 | Z15: 519 | AA15: 619 | AB15: 549 | AC15: =Z15/R15 -> 1.0196464 | AD15: =AA15/Z15 -> 1.1926782 | AE15: =AB15/AA15 -> 0.88691438 | AF15: =AB15/R15 -> 1.0785855 | AG15: =0.6*Z15+0.4*AA15 -> 559 | AH15: 5869 | AI15: =AH15/AG15 -> 10.499106 | AJ15: =AI15/AI$488 -> 2.2311054
A16: Ashreigney / Ring Ash | C16: North Tawton & Winkleigh | D16: 19 | G16: Torrington | H16: 23 | I16: Torridge | J16: 9 | K16: 2 | L16: 1 | M16: 151 | N16: 159 | O16: 625 | P16: 100 | Q16: 31 | R16: 756 | S16: =R16/N16 -> 4.754717 | T16: =O16/R16 -> 0.82671958 | U16: =P16/R16 -> 0.13227513 | V16: =Q16/R16 -> 0.041005291 | W16: =P16/O16 -> 0.16 | X16: =Q16/(O16+P16) -> 0.042758621 | Y16: =R16/R$488 -> 0.0021961486 | Z16: 752 | AA16: 858 | AB16: 1038 | AC16: =Z16/R16 -> 0.99470899 | AD16: =AA16/Z16 -> 1.1409574 | AE16: =AB16/AA16 -> 1.2097902 | AF16: =AB16/R16 -> 1.3730159 | AG16: =0.6*Z16+0.4*AA16 -> 794.4 | AH16: 2735 | AI16: =AH16/AG16 -> 3.4428499 | AJ16: =AI16/AI$488 -> 0.73162051
A17: Ashton | C17: Exminster | D17: 11 | G17: Dunsford | H17: 7 | I17: Teignbridge | J17: 5 | K17: 2 | L17: 2 | M17: 39 | N17: 42 | O17: 33 | P17: 6 | Q17: 137 | R17: 176 | S17: =R17/N17 -> 4.1904762 | T17: =O17/R17 -> 0.1875 | U17: =P17/R17 -> 0.034090909 | V17: =Q17/R17 -> 0.77840909 | W17: =P17/O17 -> 0.18181818 | X17: =Q17/(O17+P17) -> 3.5128205 | Y17: =R17/R$488 -> 0.00051127269 | Z17: 221 | AA17: 258 | AB17: 333 | AC17: =Z17/R17 -> 1.2556818 | AD17: =AA17/Z17 -> 1.1674208 | AE17: =AB17/AA17 -> 1.2906977 | AF17: =AB17/R17 -> 1.8920455 | AG17: =0.6*Z17+0.4*AA17 -> 235.8 | AH17: 1613 | AI17: =AH17/AG17 -> 6.8405428 | AJ17: =AI17/AI$488 -> 1.4536449
A18: Ashwater | C18: Black Torrington | D18: 3 | G18: Holsworthy | H18: 9 | I18: Torridge | J18: 9 | K18: 3 | L18: 2 | M18: 115 | N18: 115 | O18: 613 | P18: 28 | Q18: 2 | R18: 643 | S18: =R18/N18 -> 5.5913043 | T18: =O18/R18 -> 0.9533437 | U18: =P18/R18 -> 0.043545879 | V18: =Q18/R18 -> 0.0031104199 | W18: =P18/O18 -> 0.045676998 | X18: =Q18/(O18+P18) -> 0.0031201248 | Y18: =R18/R$488 -> 0.0018678883 | Z18: 677 | AA18: 774 | AB18: 862 | AC18: =Z18/R18 -> 1.0528771 | AD18: =AA18/Z18 -> 1.1432792 | AE18: =AB18/AA18 -> 1.1136951 | AF18: =AB18/R18 -> 1.340591 | AG18: =0.6*Z18+0.4*AA18 -> 715.8 | AH18: 1906 | AI18: =AH18/AG18 -> 2.662755 | AJ18: =AI18/AI$488 -> 0.56584695
A19: Atherington | C19: North Tawton & Winkleigh | D19: 19 | G19: Barnstaple | H19: 2 | I19: North Devon | J19: 10 | K19: 1 | L19: 4 | M19: 79 | N19: 89 | O19: 115 | P19: 30 | Q19: 339 | R19: 484 | S19: =R19/N19 -> 5.4382022 | T19: =O19/R19 -> 0.23760331 | U19: =P19/R19 -> 0.061983471 | V19: =Q19/R19 -> 0.70041322 | W19: =P19/O19 -> 0.26086957 | X19: =Q19/(O19+P19) -> 2.337931 | Y19: =R19/R$488 -> 0.0014059999 | Z19: 456 | AA19: 535 | AB19: 592 | AC19: =Z19/R19 -> 0.94214876 | AD19: =AA19/Z19 -> 1.1732456 | AE19: =AB19/AA19 -> 1.1065421 | AF19: =AB19/R19 -> 1.2231405 | AG19: =0.6*Z19+0.4*AA19 -> 487.6 | AH19: 2140 | AI19: =AH19/AG19 -> 4.3888433 | AJ19: =AI19/AI$488 -> 0.93264819
A20: Aveton Gifford | C20: Ermington | D20: 10 | G20: Woodleigh | H20: 25 | I20: South Hams | J20: 4 | K20: 4 | L20: 1 | M20: 143 | N20: 152 | O20: 143 | P20: 59 | Q20: 544 | R20: 746 | S20: =R20/N20 -> 4.9078947 | T20: =O20/R20 -> 0.19168901 | U20: =P20/R20 -> 0.079088472 | V20: =Q20/R20 -> 0.72922252 | W20: =P20/O20 -> 0.41258741 | X20: =Q20/(O20+P20) -> 2.6930693 | Y20: =R20/R$488 -> 0.002167099 | Z20: 828 | AA20: 924 | AB20: 939 | AC20: =Z20/R20 -> 1.1099196 | AD20: =AA20/Z20 -> 1.115942 | AE20: =AB20/AA20 -> 1.0162338 | AF20: =AB20/R20 -> 1.2587131 | AG20: =0.6*Z20+0.4*AA20 -> 866.4 | AH20: 5436 | AI20: =AH20/AG20 -> 6.2742382 | AJ20: =AI20/AI$488 -> 1.3333028
A21: Awliscombe | B21: 2 | C21: Hemyock | D21: 17 | G21: Dunkeswell | H21: 6 | I21: East Devon | J21: 6 | K21: 7 | L21: 3 | M21: 86 | N21: 105 | O21: 165 | P21: 194 | Q21: 67 | R21: 426 | S21: =R21/N21 -> 4.0571429 | T21: =O21/R21 -> 0.38732394 | U21: =P21/R21 -> 0.45539906 | V21: =Q21/R21 -> 0.157277 | W21: =P21/O21 -> 1.1757576 | X21: =Q21/(O21+P21) -> 0.18662953 | Y21: =R21/R$488 -> 0.0012375123 | Z21: 471 | AA21: 513 | AB21: 598 | AC21: =Z21/R21 -> 1.1056338 | AD21: =AA21/Z21 -> 1.089172 | AE21: =AB21/AA21 -> 1.165692 | AF21: =AB21/R21 -> 1.4037559 | AG21: =0.6*Z21+0.4*AA21 -> 487.8 | AH21: 3733 | AI21: =AH21/AG21 -> 7.6527265 | AJ21: =AI21/AI$488 -> 1.6262375
A22: Axminster (incl Beerhall) | B22: 1 | C22: Axminster | D22: 1 | E22: Yes | G22: Honiton | H22: 10 | I22: East Devon | J22: 6 | K22: 7 | L22: 1 | M22: 406 | N22: 411 | O22: 383 | P22: 572 | Q22: 1199 | R22: 2154 | S22: =R22/N22 -> 5.2408759 | T22: =O22/R22 -> 0.17780873 | U22: =P22/R22 -> 0.26555246 | V22: =Q22/R22 -> 0.55663881 | W22: =P22/O22 -> 1.4934726 | X22: =Q22/(O22+P22) -> 1.2554974 | Y22: =R22/R$488 -> 0.0062572806 | Z22: 2387 | AA22: 2742 | AB22: 2719 | AC22: =Z22/R22 -> 1.1081708 | AD22: =AA22/Z22 -> 1.1487222 | AE22: =AB22/AA22 -> 0.99161196 | AF22: =AB22/R22 -> 1.2623027 | AG22: =0.6*Z22+0.4*AA22 -> 2529 | AH22: 13797 | AI22: =AH22/AG22 -> 5.455516 | AJ22: =AI22/AI$488 -> 1.1593208
A23: Axmouth (incl Horsedown and Rousdon) | B23: 2 | C23: Axminster | D23: 1 | G23: Honiton | H23: 10 | I23: East Devon | J23: 6 | K23: 7 | L23: 2 | M23: 60 | N23: 66 | O23: 305 | P23: 8 | Q23: 62 | R23: 375 | S23: =R23/N23 -> 5.6818182 | T23: =O23/R23 -> 0.81333333 | U23: =P23/R23 -> 0.021333333 | V23: =Q23/R23 -> 0.16533333 | W23: =P23/O23 -> 0.026229508 | X23: =Q23/(O23+P23) -> 0.19808307 | Y23: =R23/R$488 -> 0.0010893594 | Z23: 466 | AA23: 543 | AB23: 656 | AC23: =Z23/R23 -> 1.2426667 | AD23: =AA23/Z23 -> 1.1652361 | AE23: =AB23/AA23 -> 1.2081031 | AF23: =AB23/R23 -> 1.7493333 | AG23: =0.6*Z23+0.4*AA23 -> 496.8 | AH23: 5139 | AI23: =AH23/AG23 -> 10.344203 | AJ23: =AI23/AI$488 -> 2.1981879
A24: Aylesbeare (incl Newton Poppleford) | C24: East Budleigh | D24: 9 | G24: Aylesbeare | H24: 1 | I24: East Devon | J24: 6 | K24: 6 | L24: 3 | M24: 139 | N24: 181 | O24: 366 | P24: 318 | Q24: 3 | R24: 687 | S24: =R24/N24 -> 3.7955801 | T24: =O24/R24 -> 0.53275109 | U24: =P24/R24 -> 0.4628821 | V24: =Q24/R24 -> 0.0043668122 | W24: =P24/O24 -> 0.86885246 | X24: =Q24/(O24+P24) -> 0.0043859649 | Y24: =R24/R$488 -> 0.0019957065 | Z24: 747 | AA24: 854 | AB24: 1025 | AC24: =Z24/R24 -> 1.0873362 | AD24: =AA24/Z24 -> 1.1432396 | AE24: =AB24/AA24 -> 1.2002342 | AF24: =AB24/R24 -> 1.4919942 | AG24: =0.6*Z24+0.4*AA24 -> 789.8 | AH24: 2526 | AI24: =AH24/AG24 -> 3.198278 | AJ24: =AI24/AI$488 -> 0.67964792
A25: Bampton | C25: Bampton | D25: 2 | E25: Yes | G25: Tiverton | H25: 22 | I25: Mid Devon | J25: 7 | K25: 2 | L25: 11 | M25: 279 | N25: 279 | O25: 330 | P25: 417 | Q25: 617 | R25: 1364 | S25: =R25/N25 -> 4.8888889 | T25: =O25/R25 -> 0.24193548 | U25: =P25/R25 -> 0.30571848 | V25: =Q25/R25 -> 0.45234604 | W25: =P25/O25 -> 1.2636364 | X25: =Q25/(O25+P25) -> 0.82597055 | Y25: =R25/R$488 -> 0.0039623634 | Z25: 1422 | AA25: 1633 | AB25: 1961 | AC25: =Z25/R25 -> 1.042522 | AD25: =AA25/Z25 -> 1.1483826 | AE25: =AB25/AA25 -> 1.2008573 | AF25: =AB25/R25 -> 1.4376833 | AG25: =0.6*Z25+0.4*AA25 -> 1506.4 | AH25: 7232 | AI25: =AH25/AG25 -> 4.8008497 | AJ25: =AI25/AI$488 -> 1.0202013
A26: Barnstaple | C26: Braunton | D26: 4 | E26: Yes | G26: Barnstaple | H26: 2 | I26: North Devon | J26: 10 | K26: 1 | L26: 10 | M26: 619 | N26: 828 | O26: 68 | P26: 578 | Q26: 3102 | R26: 3748 | S26: =R26/N26 -> 4.52657 | T26: =O26/R26 -> 0.01814301 | U26: =P26/R26 -> 0.15421558 | V26: =Q26/R26 -> 0.82764141 | W26: =P26/O26 -> 8.5 | X26: =Q26/(O26+P26) -> 4.8018576 | Y26: =R26/R$488 -> 0.010887784 | Z26: 4019 | AA26: 5079 | AB26: 6840 | AC26: =Z26/R26 -> 1.0723052 | AD26: =AA26/Z26 -> 1.2637472 | AE26: =AB26/AA26 -> 1.3467218 | AF26: =AB26/R26 -> 1.8249733 | AG26: =0.6*Z26+0.4*AA26 -> 4443 | AH26: 11278 | AI26: =AH26/AG26 -> 2.538375 | AJ26: =AI26/AI$488 -> 0.53941566
A27: Beaford | C27: Shebbear | D27: 23 | G27: Torrington | H27: 23 | I27: Torridge | J27: 9 | K27: 2 | L27: 6 | M27: 95 | N27: 100 | O27: 236 | P27: 30 | Q27: 250 | R27: 516 | S27: =R27/N27 -> 5.16 | T27: =O27/R27 -> 0.45736434 | U27: =P27/R27 -> 0.058139535 | V27: =Q27/R27 -> 0.48449612 | W27: =P27/O27 -> 0.12711864 | X27: =Q27/(O27+P27) -> 0.93984962 | Y27: =R27/R$488 -> 0.0014989586 | Z27: 540 | AA27: 582 | AB27: 624 | AC27: =Z27/R27 -> 1.0465116 | AD27: =AA27/Z27 -> 1.0777778 | AE27: =AB27/AA27 -> 1.0721649 | AF27: =AB27/R27 -> 1.2093023 | AG27: =0.6*Z27+0.4*AA27 -> 556.8 | AH27: 1736 | AI27: =AH27/AG27 -> 3.1178161 | AJ27: =AI27/AI$488 -> 0.66254941
A28: Beaworthy | C28: Black Torrington | D28: 3 | G28: Okehampton | H28: 14 | I28: West Devon | J28: 8 | K28: 3 | L28: 8 | M28: 35 | N28: 36 | O28: 150 | P28: 5 | Q28: 63 | R28: 218 | S28: =R28/N28 -> 6.0555556 | T28: =O28/R28 -> 0.68807339 | U28: =P28/R28 -> 0.02293578 | V28: =Q28/R28 -> 0.28899083 | W28: =P28/O28 -> 0.033333333 | X28: =Q28/(O28+P28) -> 0.40645161 | Y28: =R28/R$488 -> 0.00063328095 | Z28: 235 | AA28: 299 | AB28: 339 | AC28: =Z28/R28 -> 1.0779817 | AD28: =AA28/Z28 -> 1.2723404 | AE28: =AB28/AA28 -> 1.1337793 | AF28: =AB28/R28 -> 1.5550459 | AG28: =0.6*Z28+0.4*AA28 -> 260.6 | AH28: 878 | AI28: =AH28/AG28 -> 3.3691481 | AJ28: =AI28/AI$488 -> 0.71595855
A29: Belstone | C29: Black Torrington | D29: 3 | G29: Okehampton | H29: 14 | I29: West Devon | J29: 8 | K29: 3 | L29: 9 | M29: 29 | N29: 29 | O29: 75 | P29: 4 | Q29: 58 | R29: 137 | S29: =R29/N29 -> 4.7241379 | T29: =O29/R29 -> 0.54744526 | U29: =P29/R29 -> 0.02919708 | V29: =Q29/R29 -> 0.42335766 | W29: =P29/O29 -> 0.053333333 | X29: =Q29/(O29+P29) -> 0.73417722 | Y29: =R29/R$488 -> 0.00039797931 | Z29: 120 | AA29: 157 | AB29: 206 | AC29: =Z29/R29 -> 0.87591241 | AD29: =AA29/Z29 -> 1.3083333 | AE29: =AB29/AA29 -> 1.3121019 | AF29: =AB29/R29 -> 1.5036496 | AG29: =0.6*Z29+0.4*AA29 -> 134.8 | AH29: 696 | AI29: =AH29/AG29 -> 5.1632047 | AJ29: =AI29/AI$488 -> 1.0972033
A30: Bere Ferrers (incl Bere Alston) | C30: Roborough | D30: 22 | E30: Historically | G30: Tamerton | H30: 19 | I30: West Devon | J30: 8 | K30: 4 | L30: 7 | M30: 206 | N30: 217 | O30: 217 | P30: 38 | Q30: 855 | R30: 1110 | S30: =R30/N30 -> 5.1152074 | T30: =O30/R30 -> 0.1954955 | U30: =P30/R30 -> 0.034234234 | V30: =Q30/R30 -> 0.77027027 | W30: =P30/O30 -> 0.17511521 | X30: =Q30/(O30+P30) -> 3.3529412 | Y30: =R30/R$488 -> 0.0032245039 | Z30: 1504 | AA30: 2198 | AB30: 1876 | AC30: =Z30/R30 -> 1.354955 | AD30: =AA30/Z30 -> 1.4614362 | AE30: =AB30/AA30 -> 0.85350318 | AF30: =AB30/R30 -> 1.6900901 | AG30: =0.6*Z30+0.4*AA30 -> 1781.6 | AH30: 25559 | AI30: =AH30/AG30 -> 14.346093 | AJ30: =AI30/AI$488 -> 3.0486069
A31: Berry Pomeroy | C31: Haytor | D31: 16 | F31: Medium village | G31: Ipplepen | H31: 11 | I31: South Hams | J31: 4 | K31: 4 | L31: 16 | M31: 157 | N31: 226 | O31: 198 | P31: 324 | Q31: 602 | R31: 1124 | S31: =R31/N31 -> 4.9734513 | T31: =O31/R31 -> 0.17615658 | U31: =P31/R31 -> 0.28825623 | V31: =Q31/R31 -> 0.53558719 | W31: =P31/O31 -> 1.6363636 | X31: =Q31/(O31+P31) -> 1.1532567 | Y31: =R31/R$488 -> 0.0032651733 | Z31: 1179 | AA31: 1255 | AB31: 1186 | AC31: =Z31/R31 -> 1.0489324 | AD31: =AA31/Z31 -> 1.0644614 | AE31: =AB31/AA31 -> 0.94501992 | AF31: =AB31/R31 -> 1.0551601 | AG31: =0.6*Z31+0.4*AA31 -> 1209.4 | AH31: 7419 | AI31: =AH31/AG31 -> 6.1344468 | AJ31: =AI31/AI$488 -> 1.3035965
A32: Berrynarbour | C32: Braunton | D32: 4 | G32: Shirwell | H32: 17 | I32: North Devon | J32: 10 | K32: 1 | L32: 13 | M32: 83 | N32: 94 | O32: 501 | P32: 24 | Q32: 7 | R32: 532 | S32: =R32/N32 -> 5.6595745 | T32: =O32/R32 -> 0.94172932 | U32: =P32/R32 -> 0.045112782 | V32: =Q32/R32 -> 0.013157895 | W32: =P32/O32 -> 0.047904192 | X32: =Q32/(O32+P32) -> 0.013333333 | Y32: =R32/R$488 -> 0.0015454379 | Z32: 573 | AA32: 648 | AB32: 794 | AC32: =Z32/R32 -> 1.0770677 | AD32: =AA32/Z32 -> 1.1308901 | AE32: =AB32/AA32 -> 1.2253086 | AF32: =AB32/R32 -> 1.4924812 | AG32: =0.6*Z32+0.4*AA32 -> 603 | AH32: 3959 | AI32: =AH32/AG32 -> 6.5655058 | AJ32: =AI32/AI$488 -> 1.3951984
A33: Bickington | C33: Teignbridge | D33: 28 | G33: Moreton | H33: 13 | I33: Teignbridge | J33: 5 | K33: 4 | L33: 18 | M33: 40 | N33: 40 | O33: 115 | P33: 13 | Q33: 109 | R33: 237 | S33: =R33/N33 -> 5.925 | T33: =O33/R33 -> 0.48523207 | U33: =P33/R33 -> 0.054852321 | V33: =Q33/R33 -> 0.45991561 | W33: =P33/O33 -> 0.11304348 | X33: =Q33/(O33+P33) -> 0.8515625 | Y33: =R33/R$488 -> 0.00068847516 | Z33: 258 | AA33: 301 | AB33: 351 | AC33: =Z33/R33 -> 1.0886076 | AD33: =AA33/Z33 -> 1.1666667 | AE33: =AB33/AA33 -> 1.166113 | AF33: =AB33/R33 -> 1.4810127 | AG33: =0.6*Z33+0.4*AA33 -> 275.2 | AH33: 1516 | AI33: =AH33/AG33 -> 5.5087209 | AJ33: =AI33/AI$488 -> 1.170627
A34: Bickleigh (near Plymouth) | C34: Roborough | D34: 22 | G34: Tamerton | H34: 19 | I34: South Hams | J34: 4 | K34: 4 | L34: 8 | M34: 39 | N34: 51 | O34: 140 | P34: 14 | Q34: 110 | R34: 264 | S34: =R34/N34 -> 5.1764706 | T34: =O34/R34 -> 0.53030303 | U34: =P34/R34 -> 0.053030303 | V34: =Q34/R34 -> 0.41666667 | W34: =P34/O34 -> 0.1 | X34: =Q34/(O34+P34) -> 0.71428571 | Y34: =R34/R$488 -> 0.00076690904 | Z34: 300 | AA34: 457 | AB34: 466 | AC34: =Z34/R34 -> 1.1363636 | AD34: =AA34/Z34 -> 1.5233333 | AE34: =AB34/AA34 -> 1.0196937 | AF34: =AB34/R34 -> 1.7651515 | AG34: =0.6*Z34+0.4*AA34 -> 362.8 | AH34: 2281 | AI34: =AH34/AG34 -> 6.2872106 | AJ34: =AI34/AI$488 -> 1.3360594
A35: Bickleigh (near Tiverton) | C35: Hayridge | D35: 15 | G35: Tiverton | H35: 22 | I35: Mid Devon | J35: 7 | K35: 2 | L35: 14 | M35: 56 | N35: 56 | O35: 73 | P35: 34 | Q35: 190 | R35: 297 | S35: =R35/N35 -> 5.3035714 | T35: =O35/R35 -> 0.24579125 | U35: =P35/R35 -> 0.11447811 | V35: =Q35/R35 -> 0.63973064 | W35: =P35/O35 -> 0.46575342 | X35: =Q35/(O35+P35) -> 1.7757009 | Y35: =R35/R$488 -> 0.00086277267 | Z35: 254 | AA35: 273 | AB35: 323 | AC35: =Z35/R35 -> 0.85521886 | AD35: =AA35/Z35 -> 1.0748031 | AE35: =AB35/AA35 -> 1.1831502 | AF35: =AB35/R35 -> 1.0875421 | AG35: =0.6*Z35+0.4*AA35 -> 261.6 | AH35: 2487 | AI35: =AH35/AG35 -> 9.5068807 | AJ35: =AI35/AI$488 -> 2.0202533
A36: Bicton (incl Dotton) | C36: East Budleigh | D36: 9 | G36: Aylesbeare | H36: 1 | I36: East Devon | J36: 6 | K36: 6 | L36: 10 | M36: 24 | N36: 36 | O36: 28 | P36: 9 | Q36: 136 | R36: 173 | S36: =R36/N36 -> 4.8055556 | T36: =O36/R36 -> 0.16184971 | U36: =P36/R36 -> 0.052023121 | V36: =Q36/R36 -> 0.78612717 | W36: =P36/O36 -> 0.32142857 | X36: =Q36/(O36+P36) -> 3.6756757 | Y36: =R36/R$488 -> 0.00050255782 | Z36: 174 | AA36: 217 | AB36: 233 | AC36: =Z36/R36 -> 1.0057803 | AD36: =AA36/Z36 -> 1.2471264 | AE36: =AB36/AA36 -> 1.0737327 | AF36: =AB36/R36 -> 1.3468208 | AG36: =0.6*Z36+0.4*AA36 -> 191.2 | AH36: 1966 | AI36: =AH36/AG36 -> 10.282427 | AJ36: =AI36/AI$488 -> 2.1850602
A37: Bideford | C37: Shebbear | D37: 23 | E37: Yes | G37: Hartland | H37: 8 | I37: Torridge | J37: 9 | K37: 1 | L37: 7 | M37: 582 | N37: 613 | O37: 126 | P37: 325 | Q37: 2536 | R37: 2987 | S37: =R37/N37 -> 4.8727569 | T37: =O37/R37 -> 0.042182792 | U37: =P37/R37 -> 0.10880482 | V37: =Q37/R37 -> 0.84901239 | W37: =P37/O37 -> 2.5793651 | X37: =Q37/(O37+P37) -> 5.6230599 | Y37: =R37/R$488 -> 0.008677111 | Z37: 3244 | AA37: 4053 | AB37: 4846 | AC37: =Z37/R37 -> 1.0860395 | AD37: =AA37/Z37 -> 1.2493835 | AE37: =AB37/AA37 -> 1.1956575 | AF37: =AB37/R37 -> 1.6223636 | AG37: =0.6*Z37+0.4*AA37 -> 3567.6 | AH37: 9312 | AI37: =AH37/AG37 -> 2.6101581 | AJ37: =AI37/AI$488 -> 0.55466989
A38: Bigbury | C38: Ermington | D38: 10 | G38: Woodleigh | H38: 25 | I38: South Hams | J38: 4 | K38: 4 | L38: 11 | M38: 90 | N38: 91 | O38: 79 | P38: 18 | Q38: 333 | R38: 430 | S38: =R38/N38 -> 4.7252747 | T38: =O38/R38 -> 0.18372093 | U38: =P38/R38 -> 0.041860465 | V38: =Q38/R38 -> 0.7744186 | W38: =P38/O38 -> 0.2278481 | X38: =Q38/(O38+P38) -> 3.4329897 | Y38: =R38/R$488 -> 0.0012491321 | Z38: 474 | AA38: 536 | AB38: 578 | AC38: =Z38/R38 -> 1.1023256 | AD38: =AA38/Z38 -> 1.1308017 | AE38: =AB38/AA38 -> 1.0783582 | AF38: =AB38/R38 -> 1.344186 | AG38: =0.6*Z38+0.4*AA38 -> 498.8 | AH38: 4147 | AI38: =AH38/AG38 -> 8.3139535 | AJ38: =AI38/AI$488 -> 1.7667511
A39: Bishops Nympton | C39: Witheridge | D39: 31 | G39: South Molton | H39: 18 | I39: North Devon | J39: 10 | K39: 1 | L39: 8 | M39: 169 | N39: 171 | O39: 350 | P39: 83 | Q39: 469 | R39: 902 | S39: =R39/N39 -> 5.2748538 | T39: =O39/R39 -> 0.38802661 | U39: =P39/R39 -> 0.092017738 | V39: =Q39/R39 -> 0.51995565 | W39: =P39/O39 -> 0.23714286 | X39: =Q39/(O39+P39) -> 1.0831409 | Y39: =R39/R$488 -> 0.0026202725 | Z39: 920 | AA39: 1096 | AB39: 1116 | AC39: =Z39/R39 -> 1.0199557 | AD39: =AA39/Z39 -> 1.1913043 | AE39: =AB39/AA39 -> 1.0182482 | AF39: =AB39/R39 -> 1.2372506 | AG39: =0.6*Z39+0.4*AA39 -> 990.4 | AH39: 6646 | AI39: =AH39/AG39 -> 6.71042 | AJ39: =AI39/AI$488 -> 1.4259933
A40: Bishops Tawton | C40: South Molton | D40: 25 | G40: Barnstaple | H40: 2 | I40: North Devon | J40: 10 | K40: 1 | L40: 9 | M40: 144 | N40: 162 | O40: 280 | P40: 42 | Q40: 425 | R40: 747 | S40: =R40/N40 -> 4.6111111 | T40: =O40/R40 -> 0.37483266 | U40: =P40/R40 -> 0.0562249 | V40: =Q40/R40 -> 0.56894244 | W40: =P40/O40 -> 0.15 | X40: =Q40/(O40+P40) -> 1.3198758 | Y40: =R40/R$488 -> 0.002170004 | Z40: 978 | AA40: 1200 | AB40: 1641 | AC40: =Z40/R40 -> 1.3092369 | AD40: =AA40/Z40 -> 1.2269939 | AE40: =AB40/AA40 -> 1.3675 | AF40: =AB40/R40 -> 2.1967871 | AG40: =0.6*Z40+0.4*AA40 -> 1066.8 | AH40: 5663 | AI40: =AH40/AG40 -> 5.308399 | AJ40: =AI40/AI$488 -> 1.1280577
A41: Bishopsteignton | C41: Exminster | D41: 11 | G41: Kenn | H41: 12 | I41: Teignbridge | J41: 5 | K41: 6 | L41: 4 | M41: 157 | N41: 159 | O41: 162 | P41: 39 | Q41: 472 | R41: 673 | S41: =R41/N41 -> 4.2327044 | T41: =O41/R41 -> 0.24071322 | U41: =P41/R41 -> 0.05794948 | V41: =Q41/R41 -> 0.7013373 | W41: =P41/O41 -> 0.24074074 | X41: =Q41/(O41+P41) -> 2.3482587 | Y41: =R41/R$488 -> 0.0019550371 | Z41: 753 | AA41: 946 | AB41: 1085 | AC41: =Z41/R41 -> 1.1188707 | AD41: =AA41/Z41 -> 1.2563081 | AE41: =AB41/AA41 -> 1.1469345 | AF41: =AB41/R41 -> 1.6121842 | AG41: =0.6*Z41+0.4*AA41 -> 830.2 | AH41: 4904 | AI41: =AH41/AG41 -> 5.9070104 | AJ41: =AI41/AI$488 -> 1.2552653
...

Sheet  Parish Types
A1: Parishes, by type | B1: Houses | C1: Families | D1: Agric | E1: Mftg | F1: Other | G1: Popn01 | H1: Pop/Fam | I1: Ag/Pop | J1: Ind/Pop | K1: Other/Pop | L1: Ind/Ag | M1: Other/A+I | N1: % of Devon | O1: Popn11 | P1: Popn21 | Q1: Popn31 | R1: Popn11/01 | S1: Popn21/11 | T1: Popn31/21 | U1: Popn31/01 | V1: Popn15 (est) | W1: Prop val 15 | X1: £/cap | Y1: £/cap %Dev
A2: Devon - whole county (1801 parishes) | B2: ='Full 1801-31 data set'!M486 -> 57962 | C2: ='Full 1801-31 data set'!N486 -> 72689 | D2: ='Full 1801-31 data set'!O486 -> 96417 | E2: ='Full 1801-31 data set'!P486 -> 62111 | F2: ='Full 1801-31 data set'!Q486 -> 182519 | G2: ='Full 1801-31 data set'!R486 -> 341047 | H2: =G2/C2 -> 4.6918653 | I2: =D2/G2 -> 0.28270883 | J2: =E2/G2 -> 0.18211859 | K2: =F2/G2 -> 0.53517257 | L2: =E2/D2 -> 0.64419138 | M2: =F2/(D2+E2) -> 1.151336 | N2: =G2/G$2 -> 1 | O2: ='Full 1801-31 data set'!Z486 -> 378778 | P2: ='Full 1801-31 data set'!AA486 -> 439057 | Q2: ='Full 1801-31 data set'!AB486 -> 494211 | R2: =O2/G2 -> 1.1106328 | S2: =P2/O2 -> 1.1591407 | T2: =Q2/P2 -> 1.1256192 | U2: =Q2/G2 -> 1.4490994 | V2: =0.6*O2+0.4*P2 -> 402889.6 | W2: ='Full 1801-31 data set'!AH486 -> 1894694 | X2: =W2/V2 -> 4.7027622 | Y2: =X2/X$2 -> 1
A3: Exeter and immediate surrounds | B3: =SUMIF('Full 1801-31 data set'!$F$4:$F$484,"Exeter",'Full 1801-31 data set'!M$4:M$484) -> 3305 | C3: =SUMIF('Full 1801-31 data set'!$F$4:$F$484,"Exeter",'Full 1801-31 data set'!N$4:N$484) -> 4658 | D3: =SUMIF('Full 1801-31 data set'!$F$4:$F$484,"Exeter",'Full 1801-31 data set'!O$4:O$484) -> 801 | E3: =SUMIF('Full 1801-31 data set'!$F$4:$F$484,"Exeter",'Full 1801-31 data set'!P$4:P$484) -> 6738 | F3: =SUMIF('Full 1801-31 data set'!$F$4:$F$484,"Exeter",'Full 1801-31 data set'!Q$4:Q$484) -> 13014 | G3: =SUMIF('Full 1801-31 data set'!$F$4:$F$484,"Exeter",'Full 1801-31 data set'!R$4:R$484) -> 20553 | H3: =G3/C3 -> 4.4124088 | I3: =D3/G3 -> 0.038972413 | J3: =E3/G3 -> 0.32783535 | K3: =F3/G3 -> 0.63319223 | L3: =E3/D3 -> 8.411985 | M3: =F3/(D3+E3) -> 1.7262236 | N3: =G3/G$2 -> 0.060264421 | O3: =SUMIF('Full 1801-31 data set'!$F$4:$F$484,"Exeter",'Full 1801-31 data set'!Z$4:Z$484) -> 22558 | P3: =SUMIF('Full 1801-31 data set'!$F$4:$F$484,"Exeter",'Full 1801-31 data set'!AA$4:AA$484) -> 28183 | Q3: =SUMIF('Full 1801-31 data set'!$F$4:$F$484,"Exeter",'Full 1801-31 data set'!AB$4:AB$484) -> 34803 | R3: =O3/G3 -> 1.0975527 | S3: =P3/O3 -> 1.2493572 | T3: =Q3/P3 -> 1.2348934 | U3: =Q3/G3 -> 1.6933294 | V3: =0.6*O3+0.4*P3 -> 24808 | W3: =SUMIF('Full 1801-31 data set'!$F$4:$F$484,"Exeter",'Full 1801-31 data set'!AH$4:AH$484) -> 78908 | X3: =W3/V3 -> 3.1807481 | Y3: =X3/X$2 -> 0.67635742
A4: Plymouth and Stoke Damerel | B4: =SUMIF('Full 1801-31 data set'!$F$4:$F$484,"Plymouth/SD",'Full 1801-31 data set'!M$4:M$484) -> 4462 | C4: =SUMIF('Full 1801-31 data set'!$F$4:$F$484,"Plymouth/SD",'Full 1801-31 data set'!N$4:N$484) -> 10724 | D4: =SUMIF('Full 1801-31 data set'!$F$4:$F$484,"Plymouth/SD",'Full 1801-31 data set'!O$4:O$484) -> 908 | E4: =SUMIF('Full 1801-31 data set'!$F$4:$F$484,"Plymouth/SD",'Full 1801-31 data set'!P$4:P$484) -> 7316 | F4: =SUMIF('Full 1801-31 data set'!$F$4:$F$484,"Plymouth/SD",'Full 1801-31 data set'!Q$4:Q$484) -> 35062 | G4: =SUMIF('Full 1801-31 data set'!$F$4:$F$484,"Plymouth/SD",'Full 1801-31 data set'!R$4:R$484) -> 43286 | H4: =G4/C4 -> 4.036367 | I4: =D4/G4 -> 0.020976759 | J4: =E4/G4 -> 0.16901539 | K4: =F4/G4 -> 0.81000785 | L4: =E4/D4 -> 8.0572687 | M4: =F4/(D4+E4) -> 4.2633755 | N4: =G4/G$2 -> 0.12692092 | O4: =SUMIF('Full 1801-31 data set'!$F$4:$F$484,"Plymouth/SD",'Full 1801-31 data set'!Z$4:Z$484) -> 56174 | P4: =SUMIF('Full 1801-31 data set'!$F$4:$F$484,"Plymouth/SD",'Full 1801-31 data set'!AA$4:AA$484) -> 61387 | Q4: =SUMIF('Full 1801-31 data set'!$F$4:$F$484,"Plymouth/SD",'Full 1801-31 data set'!AB$4:AB$484) -> 75763 | R4: =O4/G4 -> 1.2977406 | S4: =P4/O4 -> 1.0928009 | T4: =Q4/P4 -> 1.2341864 | U4: =Q4/G4 -> 1.7502888 | V4: =0.6*O4+0.4*P4 -> 58259.2 | W4: =SUMIF('Full 1801-31 data set'!$F$4:$F$484,"Plymouth/SD",'Full 1801-31 data set'!AH$4:AH$484) -> 196052 | X4: =W4/V4 -> 3.3651681 | Y4: =X4/X$2 -> 0.71557266
A5: Devon outside the two main cities | B5: =B2-B3-B4 -> 50195 | C5: =C2-C3-C4 -> 57307 | D5: =D2-D3-D4 -> 94708 | E5: =E2-E3-E4 -> 48057 | F5: =F2-F3-F4 -> 134443 | G5: =G2-G3-G4 -> 277208 | H5: =G5/C5 -> 4.837245 | I5: =D5/G5 -> 0.34164959 | J5: =E5/G5 -> 0.1733608 | K5: =F5/G5 -> 0.48498961 | L5: =E5/D5 -> 0.50742282 | M5: =F5/(D5+E5) -> 0.9417084 | N5: =G5/G$2 -> 0.81281466 | O5: =O2-O3-O4 -> 300046 | P5: =P2-P3-P4 -> 349487 | Q5: =Q2-Q3-Q4 -> 383645 | R5: =O5/G5 -> 1.0823858 | S5: =P5/O5 -> 1.1647781 | T5: =Q5/P5 -> 1.0977375 | U5: =Q5/G5 -> 1.3839608 | V5: =0.6*O5+0.4*P5 -> 319822.4 | W5: =W2-W3-W4 -> 1619734 | X5: =W5/V5 -> 5.0644795 | Y5: =X5/X$2 -> 1.0769159
A6: All market towns | B6: =B7+B8 -> 18663 | C6: =C7+C8 -> 22508 | D6: =D7+D8 -> 21509 | E6: =E7+E8 -> 25665 | F6: =F7+F8 -> 55531 | G6: =G7+G8 -> 102705 | H6: =G6/C6 -> 4.5630443 | I6: =D6/G6 -> 0.20942505 | J6: =E6/G6 -> 0.24989046 | K6: =F6/G6 -> 0.54068448 | L6: =E6/D6 -> 1.1932214 | M6: =F6/(D6+E6) -> 1.1771527 | N6: =G6/G$2 -> 0.30114618 | O6: =O7+O8 -> 111381 | P6: =P7+P8 -> 132062 | Q6: =Q7+Q8 -> 145580 | R6: =O6/G6 -> 1.084475 | S6: =P6/O6 -> 1.185678 | T6: =Q6/P6 -> 1.102361 | U6: =Q6/G6 -> 1.4174578 | V6: =0.6*O6+0.4*P6 -> 119653.4 | W6: =W7+W8 -> 467082 | X6: =W6/V6 -> 3.903625 | Y6: =X6/X$2 -> 0.83007066
A7: Market towns with continuing markets | B7: =B25+B26 -> 14900 | C7: =C25+C26 -> 18305 | D7: =D25+D26 -> 14001 | E7: =E25+E26 -> 21641 | F7: =F25+F26 -> 46332 | G7: =G25+G26 -> 81974 | H7: =G7/C7 -> 4.47823 | I7: =D7/G7 -> 0.17079806 | J7: =E7/G7 -> 0.26399834 | K7: =F7/G7 -> 0.5652036 | L7: =E7/D7 -> 1.5456753 | M7: =F7/(D7+E7) -> 1.2999271 | N7: =G7/G$2 -> 0.24035983 | O7: =O25+O26 -> 88562 | P7: =P25+P26 -> 105108 | Q7: =Q25+Q26 -> 116787 | R7: =O7/G7 -> 1.0803669 | S7: =P7/O7 -> 1.1868296 | T7: =Q7/P7 -> 1.1111143 | U7: =Q7/G7 -> 1.4246834 | V7: =0.6*O7+0.4*P7 -> 95180.4 | W7: =W25+W26 -> 347641 | X7: =W7/V7 -> 3.6524432 | Y7: =X7/X$2 -> 0.77665911
A8: Former market towns | B8: =SUMIF('Full 1801-31 data set'!$E$4:$E$484,"Historically",'Full 1801-31 data set'!M$4:M$484) -> 3763 | C8: =SUMIF('Full 1801-31 data set'!$E$4:$E$484,"Historically",'Full 1801-31 data set'!N$4:N$484) -> 4203 | D8: =SUMIF('Full 1801-31 data set'!$E$4:$E$484,"Historically",'Full 1801-31 data set'!O$4:O$484) -> 7508 | E8: =SUMIF('Full 1801-31 data set'!$E$4:$E$484,"Historically",'Full 1801-31 data set'!P$4:P$484) -> 4024 | F8: =SUMIF('Full 1801-31 data set'!$E$4:$E$484,"Historically",'Full 1801-31 data set'!Q$4:Q$484) -> 9199 | G8: =SUMIF('Full 1801-31 data set'!$E$4:$E$484,"Historically",'Full 1801-31 data set'!R$4:R$484) -> 20731 | H8: =G8/C8 -> 4.9324292 | I8: =D8/G8 -> 0.36216294 | J8: =E8/G8 -> 0.19410545 | K8: =F8/G8 -> 0.44373161 | L8: =E8/D8 -> 0.53596164 | M8: =F8/(D8+E8) -> 0.79769337 | N8: =G8/G$2 -> 0.060786343 | O8: =SUMIF('Full 1801-31 data set'!$E$4:$E$484,"Historically",'Full 1801-31 data set'!Z$4:Z$484) -> 22819 | P8: =SUMIF('Full 1801-31 data set'!$E$4:$E$484,"Historically",'Full 1801-31 data set'!AA$4:AA$484) -> 26954 | Q8: =SUMIF('Full 1801-31 data set'!$E$4:$E$484,"Historically",'Full 1801-31 data set'!AB$4:AB$484) -> 28793 | R8: =O8/G8 -> 1.1007187 | S8: =P8/O8 -> 1.1812086 | T8: =Q8/P8 -> 1.0682274 | U8: =Q8/G8 -> 1.3888862 | V8: =0.6*O8+0.4*P8 -> 24473 | W8: =SUMIF('Full 1801-31 data set'!$E$4:$E$484,"Historically",'Full 1801-31 data set'!AH$4:AH$484) -> 119441 | X8: =W8/V8 -> 4.8805214 | Y8: =X8/X$2 -> 1.0377989
A9: Other small towns / large villages (over 1,500 inhabitants) | B9: =SUMIF('Full 1801-31 data set'!$F$4:$F$484,"Large village",'Full 1801-31 data set'!M$4:M$484) -> 2150 | C9: =SUMIF('Full 1801-31 data set'!$F$4:$F$484,"Large village",'Full 1801-31 data set'!N$4:N$484) -> 2450 | D9: =SUMIF('Full 1801-31 data set'!$F$4:$F$484,"Large village",'Full 1801-31 data set'!O$4:O$484) -> 3589 | E9: =SUMIF('Full 1801-31 data set'!$F$4:$F$484,"Large village",'Full 1801-31 data set'!P$4:P$484) -> 2577 | F9: =SUMIF('Full 1801-31 data set'!$F$4:$F$484,"Large village",'Full 1801-31 data set'!Q$4:Q$484) -> 5241 | G9: =SUMIF('Full 1801-31 data set'!$F$4:$F$484,"Large village",'Full 1801-31 data set'!R$4:R$484) -> 11407 | H9: =G9/C9 -> 4.6559184 | I9: =D9/G9 -> 0.31463137 | J9: =E9/G9 -> 0.22591391 | K9: =F9/G9 -> 0.45945472 | L9: =E9/D9 -> 0.71802731 | M9: =F9/(D9+E9) -> 0.84998378 | N9: =G9/G$2 -> 0.033447003 | O9: =SUMIF('Full 1801-31 data set'!$F$4:$F$484,"Large village",'Full 1801-31 data set'!Z$4:Z$484) -> 12355 | P9: =SUMIF('Full 1801-31 data set'!$F$4:$F$484,"Large village",'Full 1801-31 data set'!AA$4:AA$484) -> 13421 | Q9: =SUMIF('Full 1801-31 data set'!$F$4:$F$484,"Large village",'Full 1801-31 data set'!AB$4:AB$484) -> 14266 | R9: =O9/G9 -> 1.0831069 | S9: =P9/O9 -> 1.0862809 | T9: =Q9/P9 -> 1.062961 | U9: =Q9/G9 -> 1.2506356 | V9: =0.6*O9+0.4*P9 -> 12781.4 | W9: =SUMIF('Full 1801-31 data set'!$F$4:$F$484,"Large village",'Full 1801-31 data set'!AH$4:AH$484) -> 55199 | X9: =W9/V9 -> 4.3186975 | Y9: =X9/X$2 -> 0.91833209
A10: Other medium villages (1,000 to 1,499 inhabitants) | B10: =SUMIF('Full 1801-31 data set'!$F$4:$F$484,"Medium village",'Full 1801-31 data set'!M$4:M$484) -> 4055 | C10: =SUMIF('Full 1801-31 data set'!$F$4:$F$484,"Medium village",'Full 1801-31 data set'!N$4:N$484) -> 4514 | D10: =SUMIF('Full 1801-31 data set'!$F$4:$F$484,"Medium village",'Full 1801-31 data set'!O$4:O$484) -> 6741 | E10: =SUMIF('Full 1801-31 data set'!$F$4:$F$484,"Medium village",'Full 1801-31 data set'!P$4:P$484) -> 3077 | F10: =SUMIF('Full 1801-31 data set'!$F$4:$F$484,"Medium village",'Full 1801-31 data set'!Q$4:Q$484) -> 11491 | G10: =SUMIF('Full 1801-31 data set'!$F$4:$F$484,"Medium village",'Full 1801-31 data set'!R$4:R$484) -> 21309 | H10: =G10/C10 -> 4.7206469 | I10: =D10/G10 -> 0.31634521 | J10: =E10/G10 -> 0.14439908 | K10: =F10/G10 -> 0.53925571 | L10: =E10/D10 -> 0.45646047 | M10: =F10/(D10+E10) -> 1.1704013 | N10: =G10/G$2 -> 0.062481124 | O10: =SUMIF('Full 1801-31 data set'!$F$4:$F$484,"Medium village",'Full 1801-31 data set'!Z$4:Z$484) -> 23067 | P10: =SUMIF('Full 1801-31 data set'!$F$4:$F$484,"Medium village",'Full 1801-31 data set'!AA$4:AA$484) -> 26814 | Q10: =SUMIF('Full 1801-31 data set'!$F$4:$F$484,"Medium village",'Full 1801-31 data set'!AB$4:AB$484) -> 29325 | R10: =O10/G10 -> 1.0825004 | S10: =P10/O10 -> 1.1624398 | T10: =Q10/P10 -> 1.0936451 | U10: =Q10/G10 -> 1.3761791 | V10: =0.6*O10+0.4*P10 -> 24565.8 | W10: =SUMIF('Full 1801-31 data set'!$F$4:$F$484,"Medium village",'Full 1801-31 data set'!AH$4:AH$484) -> 136973 | X10: =W10/V10 -> 5.5757598 | Y10: =X10/X$2 -> 1.1856351
A11: Small villages and hamlets (under 1,000 inhabitants) | B11: =B5-B6-B9-B10 -> 25327 | C11: =C5-C6-C9-C10 -> 27835 | D11: =D5-D6-D9-D10 -> 62869 | E11: =E5-E6-E9-E10 -> 16738 | F11: =F5-F6-F9-F10 -> 62180 | G11: =G5-G6-G9-G10 -> 141787 | H11: =G11/C11 -> 5.0938387 | I11: =D11/G11 -> 0.44340454 | J11: =E11/G11 -> 0.11805031 | K11: =F11/G11 -> 0.43854514 | L11: =E11/D11 -> 0.26623614 | M11: =F11/(D11+E11) -> 0.78108709 | N11: =G11/G$2 -> 0.41574035 | O11: =O5-O6-O9-O10 -> 153243 | P11: =P5-P6-P9-P10 -> 177190 | Q11: =Q5-Q6-Q9-Q10 -> 194474 | R11: =O11/G11 -> 1.0807973 | S11: =P11/O11 -> 1.1562681 | T11: =Q11/P11 -> 1.097545 | U11: =Q11/G11 -> 1.3715926 | V11: =0.6*O11+0.4*P11 -> 162821.8 | W11: =W5-W6-W9-W10 -> 960480 | X11: =W11/V11 -> 5.8989644 | Y11: =X11/X$2 -> 1.2543616
A14: User-defined Parish or Group of Parishes 1 | B14: =SUMIF('Full 1801-31 data set'!$B$4:$B$484,1,'Full 1801-31 data set'!M$4:M$484) -> 1438 | C14: =SUMIF('Full 1801-31 data set'!$B$4:$B$484,1,'Full 1801-31 data set'!N$4:N$484) -> 1555 | D14: =SUMIF('Full 1801-31 data set'!$B$4:$B$484,1,'Full 1801-31 data set'!O$4:O$484) -> 888 | E14: =SUMIF('Full 1801-31 data set'!$B$4:$B$484,1,'Full 1801-31 data set'!P$4:P$484) -> 2172 | F14: =SUMIF('Full 1801-31 data set'!$B$4:$B$484,1,'Full 1801-31 data set'!Q$4:Q$484) -> 4364 | G14: =SUMIF('Full 1801-31 data set'!$B$4:$B$484,1,'Full 1801-31 data set'!R$4:R$484) -> 7424 | H14: =G14/C14 -> 4.7742765 | I14: =D14/G14 -> 0.11961207 | J14: =E14/G14 -> 0.29256466 | K14: =F14/G14 -> 0.58782328 | L14: =E14/D14 -> 2.4459459 | M14: =F14/(D14+E14) -> 1.4261438 | N14: =G14/G$2 -> 0.021768261 | O14: =SUMIF('Full 1801-31 data set'!$B$4:$B$484,1,'Full 1801-31 data set'!Z$4:Z$484) -> 8584 | P14: =SUMIF('Full 1801-31 data set'!$B$4:$B$484,1,'Full 1801-31 data set'!AA$4:AA$484) -> 10730 | Q14: =SUMIF('Full 1801-31 data set'!$B$4:$B$484,1,'Full 1801-31 data set'!AB$4:AB$484) -> 11536 | R14: =O14/G14 -> 1.15625 | S14: =P14/O14 -> 1.25 | T14: =Q14/P14 -> 1.0751165 | U14: =Q14/G14 -> 1.5538793 | V14: =0.6*O14+0.4*P14 -> 9442.4 | W14: =SUMIF('Full 1801-31 data set'!$B$4:$B$484,1,'Full 1801-31 data set'!AH$4:AH$484) -> 47038 | X14: =W14/V14 -> 4.9815725 | Y14: =X14/X$2 -> 1.0592865
A15: User-defined Parish or Group of Parishes 2 | B15: =SUMIF('Full 1801-31 data set'!$B$4:$B$484,2,'Full 1801-31 data set'!M$4:M$484) -> 1083 | C15: =SUMIF('Full 1801-31 data set'!$B$4:$B$484,2,'Full 1801-31 data set'!N$4:N$484) -> 1216 | D15: =SUMIF('Full 1801-31 data set'!$B$4:$B$484,2,'Full 1801-31 data set'!O$4:O$484) -> 1716 | E15: =SUMIF('Full 1801-31 data set'!$B$4:$B$484,2,'Full 1801-31 data set'!P$4:P$484) -> 971 | F15: =SUMIF('Full 1801-31 data set'!$B$4:$B$484,2,'Full 1801-31 data set'!Q$4:Q$484) -> 3223 | G15: =SUMIF('Full 1801-31 data set'!$B$4:$B$484,2,'Full 1801-31 data set'!R$4:R$484) -> 5910 | H15: =G15/C15 -> 4.8601974 | I15: =D15/G15 -> 0.29035533 | J15: =E15/G15 -> 0.1642978 | K15: =F15/G15 -> 0.54534687 | L15: =E15/D15 -> 0.56585082 | M15: =F15/(D15+E15) -> 1.199479 | N15: =G15/G$2 -> 0.01732899 | O15: =SUMIF('Full 1801-31 data set'!$B$4:$B$484,2,'Full 1801-31 data set'!Z$4:Z$484) -> 6221 | P15: =SUMIF('Full 1801-31 data set'!$B$4:$B$484,2,'Full 1801-31 data set'!AA$4:AA$484) -> 6952 | Q15: =SUMIF('Full 1801-31 data set'!$B$4:$B$484,2,'Full 1801-31 data set'!AB$4:AB$484) -> 7447 | R15: =O15/G15 -> 1.0526227 | S15: =P15/O15 -> 1.1175052 | T15: =Q15/P15 -> 1.0712025 | U15: =Q15/G15 -> 1.2600677 | V15: =0.6*O15+0.4*P15 -> 6513.4 | W15: =SUMIF('Full 1801-31 data set'!$B$4:$B$484,2,'Full 1801-31 data set'!AH$4:AH$484) -> 47704 | X15: =W15/V15 -> 7.3239783 | Y15: =X15/X$2 -> 1.557378
A16: User-defined Parish or Group of Parishes 3 | B16: =SUMIF('Full 1801-31 data set'!$B$4:$B$484,3,'Full 1801-31 data set'!M$4:M$484) -> 245 | C16: =SUMIF('Full 1801-31 data set'!$B$4:$B$484,3,'Full 1801-31 data set'!N$4:N$484) -> 271 | D16: =SUMIF('Full 1801-31 data set'!$B$4:$B$484,3,'Full 1801-31 data set'!O$4:O$484) -> 996 | E16: =SUMIF('Full 1801-31 data set'!$B$4:$B$484,3,'Full 1801-31 data set'!P$4:P$484) -> 160 | F16: =SUMIF('Full 1801-31 data set'!$B$4:$B$484,3,'Full 1801-31 data set'!Q$4:Q$484) -> 270 | G16: =SUMIF('Full 1801-31 data set'!$B$4:$B$484,3,'Full 1801-31 data set'!R$4:R$484) -> 1426 | H16: =G16/C16 -> 5.2619926 | I16: =D16/G16 -> 0.69845722 | J16: =E16/G16 -> 0.11220196 | K16: =F16/G16 -> 0.18934081 | L16: =E16/D16 -> 0.16064257 | M16: =F16/(D16+E16) -> 0.23356401 | N16: =G16/G$2 -> 0.0041812419 | O16: =SUMIF('Full 1801-31 data set'!$B$4:$B$484,3,'Full 1801-31 data set'!Z$4:Z$484) -> 1436 | P16: =SUMIF('Full 1801-31 data set'!$B$4:$B$484,3,'Full 1801-31 data set'!AA$4:AA$484) -> 1814 | Q16: =SUMIF('Full 1801-31 data set'!$B$4:$B$484,3,'Full 1801-31 data set'!AB$4:AB$484) -> 1878 | R16: =O16/G16 -> 1.0070126 | S16: =P16/O16 -> 1.2632312 | T16: =Q16/P16 -> 1.0352811 | U16: =Q16/G16 -> 1.3169705 | V16: =0.6*O16+0.4*P16 -> 1587.2 | W16: =SUMIF('Full 1801-31 data set'!$B$4:$B$484,3,'Full 1801-31 data set'!AH$4:AH$484) -> 12271 | X16: =W16/V16 -> 7.7312248 | Y16: =X16/X$2 -> 1.6439753
A17: User-defined Parish or Group of Parishes 4 | B17: =SUMIF('Full 1801-31 data set'!$B$4:$B$484,4,'Full 1801-31 data set'!M$4:M$484) -> 695 | C17: =SUMIF('Full 1801-31 data set'!$B$4:$B$484,4,'Full 1801-31 data set'!N$4:N$484) -> 736 | D17: =SUMIF('Full 1801-31 data set'!$B$4:$B$484,4,'Full 1801-31 data set'!O$4:O$484) -> 1566 | E17: =SUMIF('Full 1801-31 data set'!$B$4:$B$484,4,'Full 1801-31 data set'!P$4:P$484) -> 535 | F17: =SUMIF('Full 1801-31 data set'!$B$4:$B$484,4,'Full 1801-31 data set'!Q$4:Q$484) -> 1332 | G17: =SUMIF('Full 1801-31 data set'!$B$4:$B$484,4,'Full 1801-31 data set'!R$4:R$484) -> 3433 | H17: =G17/C17 -> 4.6644022 | I17: =D17/G17 -> 0.45616079 | J17: =E17/G17 -> 0.15584037 | K17: =F17/G17 -> 0.38799883 | L17: =E17/D17 -> 0.34163474 | M17: =F17/(D17+E17) -> 0.63398382 | N17: =G17/G$2 -> 0.010066061 | O17: =SUMIF('Full 1801-31 data set'!$B$4:$B$484,4,'Full 1801-31 data set'!Z$4:Z$484) -> 3625 | P17: =SUMIF('Full 1801-31 data set'!$B$4:$B$484,4,'Full 1801-31 data set'!AA$4:AA$484) -> 4313 | Q17: =SUMIF('Full 1801-31 data set'!$B$4:$B$484,4,'Full 1801-31 data set'!AB$4:AB$484) -> 4577 | R17: =O17/G17 -> 1.0559278 | S17: =P17/O17 -> 1.1897931 | T17: =Q17/P17 -> 1.0612103 | U17: =Q17/G17 -> 1.3332362 | V17: =0.6*O17+0.4*P17 -> 3900.2 | W17: =SUMIF('Full 1801-31 data set'!$B$4:$B$484,4,'Full 1801-31 data set'!AH$4:AH$484) -> 22315 | X17: =W17/V17 -> 5.7215015 | Y17: =X17/X$2 -> 1.2166257
A18: User-defined Parish or Group of Parishes 5 | B18: =SUMIF('Full 1801-31 data set'!$B$4:$B$484,5,'Full 1801-31 data set'!M$4:M$484) -> 855 | C18: =SUMIF('Full 1801-31 data set'!$B$4:$B$484,5,'Full 1801-31 data set'!N$4:N$484) -> 1032 | D18: =SUMIF('Full 1801-31 data set'!$B$4:$B$484,5,'Full 1801-31 data set'!O$4:O$484) -> 2232 | E18: =SUMIF('Full 1801-31 data set'!$B$4:$B$484,5,'Full 1801-31 data set'!P$4:P$484) -> 908 | F18: =SUMIF('Full 1801-31 data set'!$B$4:$B$484,5,'Full 1801-31 data set'!Q$4:Q$484) -> 2031 | G18: =SUMIF('Full 1801-31 data set'!$B$4:$B$484,5,'Full 1801-31 data set'!R$4:R$484) -> 5171 | H18: =G18/C18 -> 5.0106589 | I18: =D18/G18 -> 0.43163798 | J18: =E18/G18 -> 0.17559466 | K18: =F18/G18 -> 0.39276736 | L18: =E18/D18 -> 0.40681004 | M18: =F18/(D18+E18) -> 0.64681529 | N18: =G18/G$2 -> 0.015162133 | O18: =SUMIF('Full 1801-31 data set'!$B$4:$B$484,5,'Full 1801-31 data set'!Z$4:Z$484) -> 5018 | P18: =SUMIF('Full 1801-31 data set'!$B$4:$B$484,5,'Full 1801-31 data set'!AA$4:AA$484) -> 5888 | Q18: =SUMIF('Full 1801-31 data set'!$B$4:$B$484,5,'Full 1801-31 data set'!AB$4:AB$484) -> 6017 | R18: =O18/G18 -> 0.97041191 | S18: =P18/O18 -> 1.1733758 | T18: =Q18/P18 -> 1.021909 | U18: =Q18/G18 -> 1.1636047 | V18: =0.6*O18+0.4*P18 -> 5366 | W18: =SUMIF('Full 1801-31 data set'!$B$4:$B$484,5,'Full 1801-31 data set'!AH$4:AH$484) -> 32464 | X18: =W18/V18 -> 6.0499441 | Y18: =X18/X$2 -> 1.2864661
A24: INTERMEDIATE WORKING SUB-TOTALS
A25: Market towns with continuing markets (single parishes) | B25: =SUMIF('Full 1801-31 data set'!$E$4:$E$484,"Yes",'Full 1801-31 data set'!M$4:M$484) -> 13793 | C25: =SUMIF('Full 1801-31 data set'!$E$4:$E$484,"Yes",'Full 1801-31 data set'!N$4:N$484) -> 16490 | D25: =SUMIF('Full 1801-31 data set'!$E$4:$E$484,"Yes",'Full 1801-31 data set'!O$4:O$484) -> 13333 | E25: =SUMIF('Full 1801-31 data set'!$E$4:$E$484,"Yes",'Full 1801-31 data set'!P$4:P$484) -> 19416 | F25: =SUMIF('Full 1801-31 data set'!$E$4:$E$484,"Yes",'Full 1801-31 data set'!Q$4:Q$484) -> 41922 | G25: =SUMIF('Full 1801-31 data set'!$E$4:$E$484,"Yes",'Full 1801-31 data set'!R$4:R$484) -> 74671 | H25: =G25/C25 -> 4.5282596 | I25: =D25/G25 -> 0.1785566 | J25: =E25/G25 -> 0.26002062 | K25: =F25/G25 -> 0.56142277 | L25: =E25/D25 -> 1.4562364 | M25: =F25/(D25+E25) -> 1.2801002 | N25: =G25/G$2 -> 0.21894636 | O25: =SUMIF('Full 1801-31 data set'!$E$4:$E$484,"Yes",'Full 1801-31 data set'!Z$4:Z$484) -> 80341 | P25: =SUMIF('Full 1801-31 data set'!$E$4:$E$484,"Yes",'Full 1801-31 data set'!AA$4:AA$484) -> 95502 | Q25: =SUMIF('Full 1801-31 data set'!$E$4:$E$484,"Yes",'Full 1801-31 data set'!AB$4:AB$484) -> 106609 | R25: =O25/G25 -> 1.0759331 | S25: =P25/O25 -> 1.1887081 | T25: =Q25/P25 -> 1.1163012 | U25: =Q25/G25 -> 1.4277162 | V25: =0.6*O25+0.4*P25 -> 86405.4 | W25: =SUMIF('Full 1801-31 data set'!$E$4:$E$484,"Yes",'Full 1801-31 data set'!AH$4:AH$484) -> 314812 | X25: =W25/V25 -> 3.6434297 | Y25: =X25/X$2 -> 0.77474248
A26: Market towns with continuing markets (multiple parishes) | B26: =SUMIF('Full 1801-31 data set'!$E$4:$E$484,"Yes (part)",'Full 1801-31 data set'!M$4:M$484) -> 1107 | C26: =SUMIF('Full 1801-31 data set'!$E$4:$E$484,"Yes (part)",'Full 1801-31 data set'!N$4:N$484) -> 1815 | D26: =SUMIF('Full 1801-31 data set'!$E$4:$E$484,"Yes (part)",'Full 1801-31 data set'!O$4:O$484) -> 668 | E26: =SUMIF('Full 1801-31 data set'!$E$4:$E$484,"Yes (part)",'Full 1801-31 data set'!P$4:P$484) -> 2225 | F26: =SUMIF('Full 1801-31 data set'!$E$4:$E$484,"Yes (part)",'Full 1801-31 data set'!Q$4:Q$484) -> 4410 | G26: =SUMIF('Full 1801-31 data set'!$E$4:$E$484,"Yes (part)",'Full 1801-31 data set'!R$4:R$484) -> 7303 | H26: =G26/C26 -> 4.0236915 | I26: =D26/G26 -> 0.091469259 | J26: =E26/G26 -> 0.30466931 | K26: =F26/G26 -> 0.60386143 | L26: =E26/D26 -> 3.3308383 | M26: =F26/(D26+E26) -> 1.5243692 | N26: =G26/G$2 -> 0.021413471 | O26: =SUMIF('Full 1801-31 data set'!$E$4:$E$484,"Yes (part)",'Full 1801-31 data set'!Z$4:Z$484) -> 8221 | P26: =SUMIF('Full 1801-31 data set'!$E$4:$E$484,"Yes (part)",'Full 1801-31 data set'!AA$4:AA$484) -> 9606 | Q26: =SUMIF('Full 1801-31 data set'!$E$4:$E$484,"Yes (part)",'Full 1801-31 data set'!AB$4:AB$484) -> 10178 | R26: =O26/G26 -> 1.1257018 | S26: =P26/O26 -> 1.168471 | T26: =Q26/P26 -> 1.0595461 | U26: =Q26/G26 -> 1.3936738 | V26: =0.6*O26+0.4*P26 -> 8775 | W26: =SUMIF('Full 1801-31 data set'!$E$4:$E$484,"Yes (part)",'Full 1801-31 data set'!AH$4:AH$484) -> 32829 | X26: =W26/V26 -> 3.7411966 | Y26: =X26/X$2 -> 0.79553173

Sheet Hundreds
A1: Hundreds | B1: Houses | C1: Families | D1: Agric | E1: Mftg | F1: Other | G1: Popn01 | H1: Pop/Fam | I1: Ag/Pop | J1: Ind/Pop | K1: Other/Pop | L1: Ind/Ag | M1: Other/A+I | N1: % of Devon | O1: Popn11 | P1: Popn21 | Q1: Popn31 | R1: Popn11/01 | S1: Popn21/11 | T1: Popn31/21 | U1: Popn31/01 | V1: Popn15 (est) | W1: Prop val 15 | X1: £/cap | Y1: £/cap %Dev
A2: Axminster | B2: =SUMIF('Full 1801-31 data set'!$D$4:$D$484,1,'Full 1801-31 data set'!M$4:M$484) -> 2051 | C2: =SUMIF('Full 1801-31 data set'!$D$4:$D$484,1,'Full 1801-31 data set'!N$4:N$484) -> 2211 | D2: =SUMIF('Full 1801-31 data set'!$D$4:$D$484,1,'Full 1801-31 data set'!O$4:O$484) -> 4031 | E2: =SUMIF('Full 1801-31 data set'!$D$4:$D$484,1,'Full 1801-31 data set'!P$4:P$484) -> 2807 | F2: =SUMIF('Full 1801-31 data set'!$D$4:$D$484,1,'Full 1801-31 data set'!Q$4:Q$484) -> 3730 | G2: =SUMIF('Full 1801-31 data set'!$D$4:$D$484,1,'Full 1801-31 data set'!R$4:R$484) -> 10568 | H2: =G2/C2 -> 4.7797377 | I2: =D2/G2 -> 0.38143452 | J2: =E2/G2 -> 0.26561317 | K2: =F2/G2 -> 0.35295231 | L2: =E2/D2 -> 0.69635326 | M2: =F2/(D2+E2) -> 0.54548113 | N2: =G2/G$35 -> 0.030986931 | O2: =SUMIF('Full 1801-31 data set'!$D$4:$D$484,1,'Full 1801-31 data set'!Z$4:Z$484) -> 11394 | P2: =SUMIF('Full 1801-31 data set'!$D$4:$D$484,1,'Full 1801-31 data set'!AA$4:AA$484) -> 13282 | Q2: =SUMIF('Full 1801-31 data set'!$D$4:$D$484,1,'Full 1801-31 data set'!AB$4:AB$484) -> 13939 | R2: =O2/G2 -> 1.0781605 | S2: =P2/O2 -> 1.1657012 | T2: =Q2/P2 -> 1.0494654 | U2: =Q2/G2 -> 1.3189818 | V2: =0.6*O2+0.4*P2 -> 12149.2 | W2: =SUMIF('Full 1801-31 data set'!$D$4:$D$484,1,'Full 1801-31 data set'!AH$4:AH$484) -> 70784 | X2: =W2/V2 -> 5.8262272 | Y2: =X2/X$35 -> 1.2388947
A3: Bampton | B3: =SUMIF('Full 1801-31 data set'!$D$4:$D$484,2,'Full 1801-31 data set'!M$4:M$484) -> 1043 | C3: =SUMIF('Full 1801-31 data set'!$D$4:$D$484,2,'Full 1801-31 data set'!N$4:N$484) -> 1120 | D3: =SUMIF('Full 1801-31 data set'!$D$4:$D$484,2,'Full 1801-31 data set'!O$4:O$484) -> 1703 | E3: =SUMIF('Full 1801-31 data set'!$D$4:$D$484,2,'Full 1801-31 data set'!P$4:P$484) -> 1841 | F3: =SUMIF('Full 1801-31 data set'!$D$4:$D$484,2,'Full 1801-31 data set'!Q$4:Q$484) -> 1663 | G3: =SUMIF('Full 1801-31 data set'!$D$4:$D$484,2,'Full 1801-31 data set'!R$4:R$484) -> 5207 | H3: =G3/C3 -> 4.6491071 | I3: =D3/G3 -> 0.32705973 | J3: =E3/G3 -> 0.35356251 | K3: =F3/G3 -> 0.31937776 | L3: =E3/D3 -> 1.0810335 | M3: =F3/(D3+E3) -> 0.46924379 | N3: =G3/G$35 -> 0.01526769 | O3: =SUMIF('Full 1801-31 data set'!$D$4:$D$484,2,'Full 1801-31 data set'!Z$4:Z$484) -> 5496 | P3: =SUMIF('Full 1801-31 data set'!$D$4:$D$484,2,'Full 1801-31 data set'!AA$4:AA$484) -> 6089 | Q3: =SUMIF('Full 1801-31 data set'!$D$4:$D$484,2,'Full 1801-31 data set'!AB$4:AB$484) -> 6500 | R3: =O3/G3 -> 1.0555022 | S3: =P3/O3 -> 1.1078967 | T3: =Q3/P3 -> 1.0674988 | U3: =Q3/G3 -> 1.2483196 | V3: =0.6*O3+0.4*P3 -> 5733.2 | W3: =SUMIF('Full 1801-31 data set'!$D$4:$D$484,2,'Full 1801-31 data set'!AH$4:AH$484) -> 31102 | X3: =W3/V3 -> 5.4248936 | Y3: =X3/X$35 -> 1.1535547
A4: Black Torrington | B4: =SUMIF('Full 1801-31 data set'!$D$4:$D$484,3,'Full 1801-31 data set'!M$4:M$484) -> 2336 | C4: =SUMIF('Full 1801-31 data set'!$D$4:$D$484,3,'Full 1801-31 data set'!N$4:N$484) -> 2578 | D4: =SUMIF('Full 1801-31 data set'!$D$4:$D$484,3,'Full 1801-31 data set'!O$4:O$484) -> 6994 | E4: =SUMIF('Full 1801-31 data set'!$D$4:$D$484,3,'Full 1801-31 data set'!P$4:P$484) -> 1382 | F4: =SUMIF('Full 1801-31 data set'!$D$4:$D$484,3,'Full 1801-31 data set'!Q$4:Q$484) -> 5052 | G4: =SUMIF('Full 1801-31 data set'!$D$4:$D$484,3,'Full 1801-31 data set'!R$4:R$484) -> 13428 | H4: =G4/C4 -> 5.2086889 | I4: =D4/G4 -> 0.52085195 | J4: =E4/G4 -> 0.10291927 | K4: =F4/G4 -> 0.37622878 | L4: =E4/D4 -> 0.19759794 | M4: =F4/(D4+E4) -> 0.60315186 | N4: =G4/G$35 -> 0.039372872 | O4: =SUMIF('Full 1801-31 data set'!$D$4:$D$484,3,'Full 1801-31 data set'!Z$4:Z$484) -> 14935 | P4: =SUMIF('Full 1801-31 data set'!$D$4:$D$484,3,'Full 1801-31 data set'!AA$4:AA$484) -> 17536 | Q4: =SUMIF('Full 1801-31 data set'!$D$4:$D$484,3,'Full 1801-31 data set'!AB$4:AB$484) -> 19492 | R4: =O4/G4 -> 1.1122282 | S4: =P4/O4 -> 1.1741547 | T4: =Q4/P4 -> 1.111542 | U4: =Q4/G4 -> 1.4515937 | V4: =0.6*O4+0.4*P4 -> 15975.4 | W4: =SUMIF('Full 1801-31 data set'!$D$4:$D$484,3,'Full 1801-31 data set'!AH$4:AH$484) -> 63334 | X4: =W4/V4 -> 3.9644704 | Y4: =X4/X$35 -> 0.84300889
A5: Braunton | B5: =SUMIF('Full 1801-31 data set'!$D$4:$D$484,4,'Full 1801-31 data set'!M$4:M$484) -> 2440 | C5: =SUMIF('Full 1801-31 data set'!$D$4:$D$484,4,'Full 1801-31 data set'!N$4:N$484) -> 2799 | D5: =SUMIF('Full 1801-31 data set'!$D$4:$D$484,4,'Full 1801-31 data set'!O$4:O$484) -> 3925 | E5: =SUMIF('Full 1801-31 data set'!$D$4:$D$484,4,'Full 1801-31 data set'!P$4:P$484) -> 1515 | F5: =SUMIF('Full 1801-31 data set'!$D$4:$D$484,4,'Full 1801-31 data set'!Q$4:Q$484) -> 7937 | G5: =SUMIF('Full 1801-31 data set'!$D$4:$D$484,4,'Full 1801-31 data set'!R$4:R$484) -> 13377 | H5: =G5/C5 -> 4.7792069 | I5: =D5/G5 -> 0.29341407 | J5: =E5/G5 -> 0.11325409 | K5: =F5/G5 -> 0.59333184 | L5: =E5/D5 -> 0.38598726 | M5: =F5/(D5+E5) -> 1.4590074 | N5: =G5/G$35 -> 0.039223333 | O5: =SUMIF('Full 1801-31 data set'!$D$4:$D$484,4,'Full 1801-31 data set'!Z$4:Z$484) -> 14287 | P5: =SUMIF('Full 1801-31 data set'!$D$4:$D$484,4,'Full 1801-31 data set'!AA$4:AA$484) -> 17927 | Q5: =SUMIF('Full 1801-31 data set'!$D$4:$D$484,4,'Full 1801-31 data set'!AB$4:AB$484) -> 21974 | R5: =O5/G5 -> 1.0680272 | S5: =P5/O5 -> 1.2547771 | T5: =Q5/P5 -> 1.2257489 | U5: =Q5/G5 -> 1.6426703 | V5: =0.6*O5+0.4*P5 -> 15743 | W5: =SUMIF('Full 1801-31 data set'!$D$4:$D$484,4,'Full 1801-31 data set'!AH$4:AH$484) -> 68679 | X5: =W5/V5 -> 4.3625103 | Y5: =X5/X$35 -> 0.9276485
A6: Cliston | B6: =SUMIF('Full 1801-31 data set'!$D$4:$D$484,5,'Full 1801-31 data set'!M$4:M$484) -> 581 | C6: =SUMIF('Full 1801-31 data set'!$D$4:$D$484,5,'Full 1801-31 data set'!N$4:N$484) -> 604 | D6: =SUMIF('Full 1801-31 data set'!$D$4:$D$484,5,'Full 1801-31 data set'!O$4:O$484) -> 1770 | E6: =SUMIF('Full 1801-31 data set'!$D$4:$D$484,5,'Full 1801-31 data set'!P$4:P$484) -> 263 | F6: =SUMIF('Full 1801-31 data set'!$D$4:$D$484,5,'Full 1801-31 data set'!Q$4:Q$484) -> 528 | G6: =SUMIF('Full 1801-31 data set'!$D$4:$D$484,5,'Full 1801-31 data set'!R$4:R$484) -> 2561 | H6: =G6/C6 -> 4.2400662 | I6: =D6/G6 -> 0.69113627 | J6: =E6/G6 -> 0.10269426 | K6: =F6/G6 -> 0.20616947 | L6: =E6/D6 -> 0.14858757 | M6: =F6/(D6+E6) -> 0.25971471 | N6: =G6/G$35 -> 0.0075092289 | O6: =SUMIF('Full 1801-31 data set'!$D$4:$D$484,5,'Full 1801-31 data set'!Z$4:Z$484) -> 2763 | P6: =SUMIF('Full 1801-31 data set'!$D$4:$D$484,5,'Full 1801-31 data set'!AA$4:AA$484) -> 3032 | Q6: =SUMIF('Full 1801-31 data set'!$D$4:$D$484,5,'Full 1801-31 data set'!AB$4:AB$484) -> 3482 | R6: =O6/G6 -> 1.0788754 | S6: =P6/O6 -> 1.0973579 | T6: =Q6/P6 -> 1.1484169 | U6: =Q6/G6 -> 1.3596251 | V6: =0.6*O6+0.4*P6 -> 2870.6 | W6: =SUMIF('Full 1801-31 data set'!$D$4:$D$484,5,'Full 1801-31 data set'!AH$4:AH$484) -> 24098 | X6: =W6/V6 -> 8.3947607 | Y6: =X6/X$35 -> 1.7850702
A7: Coleridge | B7: =SUMIF('Full 1801-31 data set'!$D$4:$D$484,6,'Full 1801-31 data set'!M$4:M$484) -> 2552 | C7: =SUMIF('Full 1801-31 data set'!$D$4:$D$484,6,'Full 1801-31 data set'!N$4:N$484) -> 3452 | D7: =SUMIF('Full 1801-31 data set'!$D$4:$D$484,6,'Full 1801-31 data set'!O$4:O$484) -> 3511 | E7: =SUMIF('Full 1801-31 data set'!$D$4:$D$484,6,'Full 1801-31 data set'!P$4:P$484) -> 3208 | F7: =SUMIF('Full 1801-31 data set'!$D$4:$D$484,6,'Full 1801-31 data set'!Q$4:Q$484) -> 8555 | G7: =SUMIF('Full 1801-31 data set'!$D$4:$D$484,6,'Full 1801-31 data set'!R$4:R$484) -> 15274 | H7: =G7/C7 -> 4.4246813 | I7: =D7/G7 -> 0.22986775 | J7: =E7/G7 -> 0.21003012 | K7: =F7/G7 -> 0.56010213 | L7: =E7/D7 -> 0.9136998 | M7: =F7/(D7+E7) -> 1.2732549 | N7: =G7/G$35 -> 0.044785616 | O7: =SUMIF('Full 1801-31 data set'!$D$4:$D$484,6,'Full 1801-31 data set'!Z$4:Z$484) -> 16529 | P7: =SUMIF('Full 1801-31 data set'!$D$4:$D$484,6,'Full 1801-31 data set'!AA$4:AA$484) -> 19018 | Q7: =SUMIF('Full 1801-31 data set'!$D$4:$D$484,6,'Full 1801-31 data set'!AB$4:AB$484) -> 20319 | R7: =O7/G7 -> 1.0821658 | S7: =P7/O7 -> 1.1505838 | T7: =Q7/P7 -> 1.0684089 | U7: =Q7/G7 -> 1.3302999 | V7: =0.6*O7+0.4*P7 -> 17524.6 | W7: =SUMIF('Full 1801-31 data set'!$D$4:$D$484,6,'Full 1801-31 data set'!AH$4:AH$484) -> 86633 | X7: =W7/V7 -> 4.943508 | Y7: =X7/X$35 -> 1.0511924
A8: Colyton | B8: =SUMIF('Full 1801-31 data set'!$D$4:$D$484,7,'Full 1801-31 data set'!M$4:M$484) -> 1036 | C8: =SUMIF('Full 1801-31 data set'!$D$4:$D$484,7,'Full 1801-31 data set'!N$4:N$484) -> 1201 | D8: =SUMIF('Full 1801-31 data set'!$D$4:$D$484,7,'Full 1801-31 data set'!O$4:O$484) -> 1455 | E8: =SUMIF('Full 1801-31 data set'!$D$4:$D$484,7,'Full 1801-31 data set'!P$4:P$484) -> 480 | F8: =SUMIF('Full 1801-31 data set'!$D$4:$D$484,7,'Full 1801-31 data set'!Q$4:Q$484) -> 3950 | G8: =SUMIF('Full 1801-31 data set'!$D$4:$D$484,7,'Full 1801-31 data set'!R$4:R$484) -> 5885 | H8: =G8/C8 -> 4.9000833 | I8: =D8/G8 -> 0.24723874 | J8: =E8/G8 -> 0.081563297 | K8: =F8/G8 -> 0.67119796 | L8: =E8/D8 -> 0.32989691 | M8: =F8/(D8+E8) -> 2.0413437 | N8: =G8/G$35 -> 0.017255686 | O8: =SUMIF('Full 1801-31 data set'!$D$4:$D$484,7,'Full 1801-31 data set'!Z$4:Z$484) -> 6088 | P8: =SUMIF('Full 1801-31 data set'!$D$4:$D$484,7,'Full 1801-31 data set'!AA$4:AA$484) -> 6971 | Q8: =SUMIF('Full 1801-31 data set'!$D$4:$D$484,7,'Full 1801-31 data set'!AB$4:AB$484) -> 7374 | R8: =O8/G8 -> 1.0344945 | S8: =P8/O8 -> 1.1450394 | T8: =Q8/P8 -> 1.0578109 | U8: =Q8/G8 -> 1.2530161 | V8: =0.6*O8+0.4*P8 -> 6441.2 | W8: =SUMIF('Full 1801-31 data set'!$D$4:$D$484,7,'Full 1801-31 data set'!AH$4:AH$484) -> 42681 | X8: =W8/V8 -> 6.6262498 | Y8: =X8/X$35 -> 1.4090123
A9: Crediton | B9: =SUMIF('Full 1801-31 data set'!$D$4:$D$484,8,'Full 1801-31 data set'!M$4:M$484) -> 1993 | C9: =SUMIF('Full 1801-31 data set'!$D$4:$D$484,8,'Full 1801-31 data set'!N$4:N$484) -> 2047 | D9: =SUMIF('Full 1801-31 data set'!$D$4:$D$484,8,'Full 1801-31 data set'!O$4:O$484) -> 3289 | E9: =SUMIF('Full 1801-31 data set'!$D$4:$D$484,8,'Full 1801-31 data set'!P$4:P$484) -> 4520 | F9: =SUMIF('Full 1801-31 data set'!$D$4:$D$484,8,'Full 1801-31 data set'!Q$4:Q$484) -> 2283 | G9: =SUMIF('Full 1801-31 data set'!$D$4:$D$484,8,'Full 1801-31 data set'!R$4:R$484) -> 10092 | H9: =G9/C9 -> 4.9301417 | I9: =D9/G9 -> 0.3259017 | J9: =E9/G9 -> 0.44787951 | K9: =F9/G9 -> 0.22621879 | L9: =E9/D9 -> 1.3742779 | M9: =F9/(D9+E9) -> 0.29235498 | N9: =G9/G$35 -> 0.029591229 | O9: =SUMIF('Full 1801-31 data set'!$D$4:$D$484,8,'Full 1801-31 data set'!Z$4:Z$484) -> 10648 | P9: =SUMIF('Full 1801-31 data set'!$D$4:$D$484,8,'Full 1801-31 data set'!AA$4:AA$484) -> 11407 | Q9: =SUMIF('Full 1801-31 data set'!$D$4:$D$484,8,'Full 1801-31 data set'!AB$4:AB$484) -> 12237 | R9: =O9/G9 -> 1.0550931 | S9: =P9/O9 -> 1.071281 | T9: =Q9/P9 -> 1.0727623 | U9: =Q9/G9 -> 1.2125446 | V9: =0.6*O9+0.4*P9 -> 10951.6 | W9: =SUMIF('Full 1801-31 data set'!$D$4:$D$484,8,'Full 1801-31 data set'!AH$4:AH$484) -> 43081 | X9: =W9/V9 -> 3.9337631 | Y9: =X9/X$35 -> 0.83647926
